test/NVDAOrders.txt
SELL GFD 1 120.1 100 1
SELL GFD 1 115.1 100 2 
SELL GFD 1 117.07 500 3 
SELL GFD 1 114.07 500 3 
BUY GFD 1 113.99 100 4
BUY GFD 1 113.59 500 4
CANCEL 1 4
BUY GFD 1 114.07 50 5
BUY GFD 1 114.0 60 6
BUY GFD 1 114.05 70 7
CANCEL 1 7
SELL GFD 1 114.08 150 8
MODIFY 1 8 SELL 114.06 150
SELL GFD 1 114.12 100 9
BUY IOC 1 114.2 100 10
BUY IOC 1 114.09 100 11
BUY IOC 1 114.21 1000 12
CANCEL 1 10
SELL GFD 1 114.13 150 12
SELL GFD 1 114.15 250 13
SELL GFD 1 114.11 500 14
BUY IOC 1 114.16 1000 15
BUY GFD 1 113.97 100 16
BUY IOC 1 114.16 1000 17
BUY IOC 1 114.06 1000 18
