TestData2.txt
SELL GFD 1 1100 100 1
SELL GFD 1 1200 100 2 
SELL GFD 1 11000 50 3 
BUY GFD 1 1000 100 4
CANCEL 1 4
BUY GFD 1 1050 50 5
CANCEL 1 5 AAPL
BUY GFD 1 1075 60 6
BUY GFD 1 1025 70 7
CANCEL 1 7
SELL GFD 1 1070 100 8
MODIFY 1 6 SELL 1065 150
SELL GFD 1 1040 100 9
BUY IOC 1 1000 100 10
BUY IOC 1 1070 100 11
CANCEL 1 10
SELL GFD 1 1100 100 12
SELL GFD 1 1200 100 13
SELL GFD 1 1000 50 14
